Workbook
Name OLE_LINK1: 'Supplem.Table 19'!$B$2

Sheet Supplem.Table 1
A1: Rock Phosphate Depletion | J1: Conventional Life Cycle Cost
B2: NB1 | C2: NB2 | D2: NB3 | E2: NB4 | F2: NB5 | G2: NB6 | H2: RP | K2: NB1 | L2: NB2 | M2: NB3 | N2: NB4 | O2: NB5 | P2: NB6 | Q2: RP
A3: NB1 | C3: 1 | D3: na | E3: na | F3: na | G3: 1 | H3: 1 | J3: NB1 | L3: 0.617 | M3: 0.692 | N3: 0.673 | O3: 0.564 | P3: 1 | Q3: 0.534
A4: NB2 | D4: 0 | E4: 0 | F4: 0 | G4: 0.046 | H4: 0.999 | J4: NB2 | M4: 0.549 | N4: 0.536 | O4: 0.324 | P4: 1 | Q4: 0.213
A5: NB3 | E5: na | F5: na | G5: 1 | H5: 1 | J5: NB3 | N5: 0.483 | O5: 0.34 | P5: 1 | Q5: 0.276
A6: NB4 | F6: na | G6: 1 | H6: 1 | J6: NB4 | O6: 0.374 | P6: 1 | Q6: 0.293
A7: NB5 | G7: 1 | H7: 1 | J7: NB5 | P7: 1 | Q7: 0.097
A8: NB6 | H8: 1 | J8: NB6 | Q8: 0
A9: RP | J9: RP
A11: Climate Change | J11: Particulate Matter
A12: NB1 | C12: 0.929 | D12: 0.983 | E12: 0.99 | F12: 0.972 | G12: 0.07 | H12: 0.999 | J12: NB1 | L12: 0.666 | M12: 0.901 | N12: 0.663 | O12: 0.985 | P12: 1 | Q12: 1
A13: NB2 | D13: 0.168 | E13: 0.172 | F13: 0.16 | G13: 0.014 | H13: 0.27 | J13: NB2 | M13: 0.548 | N13: 0.396 | O13: 0.776 | P13: 1 | Q13: 0.95
A14: NB3 | E14: 0.564 | F14: 0.408 | G14: 0.022 | H14: 0.992 | J14: NB3 | N14: 0.115 | O14: 0.954 | P14: 1 | Q14: 0.998
A15: NB4 | F15: 0.34 | G15: 0.024 | H15: 0.995 | J15: NB4 | O15: 0.998 | P15: 1 | Q15: 1
A16: NB5 | G16: 0.028 | H16: 1 | J16: NB5 | P16: 1 | Q16: 1
A17: NB6 | H17: 0.989 | J17: NB6 | Q17: 0
A18: RP | J18: RP
A20: Freshwater Eutrophication - aquatic | J20: Marine Eutrophication - aquatic
B21: NB1 | C21: NB2 | D21: NB3 | E21: NB4 | F21: NB5 | G21: NB6 | H21: RP | K21: NB1 | L21: NB2 | M21: NB3 | N21: NB4 | O21: NB5 | P21: NB6 | Q21: RP
A22: NB1 | C22: 0 | D22: 0.917 | E22: 0.513 | F22: 0.539 | G22: 0 | H22: 0.579 | J22: NB1 | L22: 0.093 | M22: 0.47 | N22: 0.465 | O22: 0.477 | P22: 0.162 | Q22: 0.484
A23: NB2 | D23: 1 | E23: 1 | F23: 1 | G23: 0.018 | H23: 1 | J23: NB2 | M23: 0.899 | N23: 1 | O23: 0.899 | P23: 0.632 | Q23: 0.9
A24: NB3 | E24: 0.36 | F24: 0.097 | G24: 0 | H24: 0.117 | J24: NB3 | N24: 0.584 | O24: 0.742 | P24: 0.162 | Q24: 0.879
A25: NB4 | F25: 0.5 | G25: 0 | H25: 0.523 | J25: NB4 | O25: 0.693 | P25: 0.162 | Q25: 0.86
A26: NB5 | G26: 0 | H26: 0.54 | J26: NB5 | P26: 0.159 | Q26: 0.99
A27: NB6 | H27: 1 | J27: NB6 | Q27: 0.841
A28: RP | J28: RP
A30: Ecotoxicity | J30: Human Toxicity - non-cancer
B31: NB1 | C31: NB2 | D31: NB3 | E31: NB4 | F31: NB5 | G31: NB6 | H31: RP | K31: NB1 | L31: NB2 | M31: NB3 | N31: NB4 | O31: NB5 | P31: NB6 | Q31: RP
A32: NB1 | C32: 0.997 | D32: 1 | E32: 0.037 | F32: 0.905 | G32: 0.692 | H32: 0.923 | J32: NB1 | L32: 0.996 | M32: 1 | N32: 0.034 | O32: 0.937 | P32: 0.582 | Q32: 0.963
A33: NB2 | D33: 1 | E33: 0 | F33: 0.005 | G33: 0 | H33: 0.01 | J33: NB2 | M33: 1 | N33: 0 | O33: 0.018 | P33: 0 | Q33: 0.028
A34: NB3 | E34: 0 | F34: 0 | G34: 0 | H34: 0 | J34: NB3 | N34: 0 | O34: 0 | P34: 0 | Q34: 0
A35: NB4 | F35: 1 | G35: 1 | H35: 1 | J35: NB4 | O35: 1 | P35: 1 | Q35: 1
A36: NB5 | G36: 0.024 | H36: 0.546 | J36: NB5 | P36: 0 | Q36: 0.644
A37: NB6 | H37: 0.982 | J37: NB6 | Q37: 1
A38: RP | J38: RP
A40: Human Toxicity - cancer | J40: Terrestrial Acidification
B41: NB1 | C41: NB2 | D41: NB3 | E41: NB4 | F41: NB5 | G41: NB6 | H41: RP | K41: NB1 | L41: NB2 | M41: NB3 | N41: NB4 | O41: NB5 | P41: NB6 | Q41: RP
A42: NB1 | C42: 0.986 | D42: 1 | E42: 0.926 | F42: 0.877 | G42: 0.999 | H42: 0.998 | J42: NB1 | L42: 0.002 | M42: 0.566 | N42: 0.511 | O42: 0.996 | P42: 0.156 | Q42: 0.997
A43: NB2 | D43: 0.999 | E43: 0.027 | F43: 0 | G43: 1 | H43: 0.92 | J43: NB2 | M43: 0.999 | N43: 0.998 | O43: 1 | P43: 0.965 | Q43: 1
A44: NB3 | E44: 0 | F44: 0 | G44: 0.324 | H44: 0.01 | J44: NB3 | N44: 0.422 | O44: 1 | P44: 0.136 | Q44: 1
...

Sheet Supplem.Table 2
H4: NB1 | L4: NB2 | P4: NB3 | T4: NB4 | X4: NB5 | AB4: NB6 | AF4: RP
A5: Number (#) | B5: Process | C5: Sub-process | D5: Parameter name | E5: Description | F5: Unit | G5: Type of distribution | H5: c (default) | I5: a (min) | J5: b (max) | K5: σ2 (variance) | L5: c (default) | M5: a (min) | N5: b (max) | O5: σ2 (variance) | P5: c (default) | Q5: a (min) | R5: b (max) | S5: σ2 (variance) | T5: c (default) | U5: a (min) | V5: b (max) | W5: σ2 (variance) | X5: c | Y5: a (min) | Z5: b (max) | AA5: σ2 (variance) | AB5: c | AC5: a (min) | AD5: b (max) | AE5: σ2 (variance) | AF5: c | AG5: a (min) | AH5: b (max) | AI5: σ2 (variance) | AJ5: Comments
A6: Technical parameters
A7: 1 | B7: Feedstock Composition | C7: Feedstock Composition | D7: Energy_BM | E7: Energy content, dry basis | F7: MJ/kg TS | G7: ND | H7: 18.8 | K7: 3.8809 | L7: 15.3 | O7: 0.7921 | P7: 18.8 | S7: 3.8809 | T7: 18.8 | W7: 3.8809 | X7: 10.1 | AA7: 7.5625 | AB7: 18.8 | AE7: 0.0625 | AF7: 0 | AI7: 0 | AJ7: ref. 4 for NB2, NB5, and NB6, refs. 5-8 NB1, NB3, and NB4, and ref. 9 for RP
A8: 2 | B8: Feedstock Composition | C8: Feedstock Composition | D8: Cbioand_BM | E8: C content, dry basis | F8: %TS | G8: ND | H8: 40.3 | K8: 16.2409 | L8: 39.1 | O8: 52.2729 | P8: 40.3 | S8: 16.2409 | T8: 40.3 | W8: 16.2409 | X8: 39 | AA8: 50.6944 | AB8: 35 | AE8: 4.5369 | AF8: 0 | AI8: 0 | AJ8: ref. 4 for NB2, NB5, and NB6, refs. 5-8 NB1, NB3, and NB4, and ref. 9 for RP
A9: 3 | B9: Feedstock Composition | C9: Feedstock Composition | D9: N_BM | E9: N content, dry basis | F9: %TS | G9: ND | H9: 4.39 | K9: 2.7889 | L9: 4.2 | O9: 1.8225 | P9: 4.39 | S9: 2.7889 | T9: 4.39 | W9: 2.7889 | X9: 9.1 | AA9: 2.5921 | AB9: 5 | AE9: 0.7225 | AF9: 0 | AI9: 0 | AJ9: ref. 4 for NB2, NB5, and NB6, refs. 5-8 NB1, NB3, and NB4, and ref. 9 for RP
A10: 4 | B10: Feedstock Composition | C10: Feedstock Composition | D10: P_BM | E10: P content, dry basis | F10: %TS | G10: ND | H10: 2.45 | K10: 0.3955781 | L10: 1.4016 | O10: 0.47280751 | P10: 2.45 | S10: 0.3955781 | T10: 2.45 | W10: 0.3955781 | X10: 3.3 | AA10: 3.953496 | AB10: 1.1 | AE10: 0.10555762 | AF10: 13.49 | AI10: 7.599217 | AJ10: ref. 4 for NB2, NB5, and NB6, refs. 5-8 NB1, NB3, and NB4, and ref. 9 for RP
A11: 5 | B11: Feedstock Composition | C11: Feedstock Composition | D11: K_BM | E11: K content, dry basis | F11: %TS | G11: ND | H11: 0.263 | K11: 0.058452733 | L11: 2.4967 | O11: 0.69177479 | P11: 0.263 | S11: 0.058452733 | T11: 0.263 | W11: 0.058452733 | X11: 5.7 | AA11: 0.011395563 | AB11: 1.6 | AE11: 0.0095355225 | AF11: 0.10748889 | AI11: 0.0059423786 | AJ11: ref. 4 for NB2, NB5, and NB6, refs. 5-8 NB1, NB3, and NB4, and ref. 9 for RP
A12: 6 | B12: Feedstock Composition | C12: Feedstock Composition | D12: As_BM | E12: As content, dry basis | F12: %TS | G12: ND | H12: 0.0004 | K12: 2.5e-07 | L12: 3.56e-05 | O12: 1e-08 | P12: 0.0004 | S12: 2.5e-07 | T12: 0.0004 | W12: 2.5e-07 | X12: 0 | AA12: 0 | AB12: 0.00021 | AE12: 2.5e-07 | AF12: 0.00075303103 | AI12: 0 | AJ12: ref. 4 for NB2, NB5, and NB6, refs. 5-8 NB1, NB3, and NB4, and ref. 9 for RP
A13: 7 | B13: Feedstock Composition | C13: Feedstock Composition | D13: Hg_BM | E13: Hg content, dry basis | F13: %TS | G13: ND | H13: 5.9e-05 | K13: 1.37e-08 | L13: 0 | O13: 0 | P13: 5.9e-05 | S13: 1.37e-08 | T13: 5.9e-05 | W13: 1.37e-08 | X13: 5e-05 | AA13: 3.24e-08 | AB13: 2e-05 | AE13: 0 | AF13: 0 | AI13: 0 | AJ13: ref. 4 for NB2, NB5, and NB6, refs. 5-8 NB1, NB3, and NB4, and ref. 9 for RP
A14: 8 | B14: Feedstock Composition | C14: Feedstock Composition | D14: Cd_BM | E14: Cd content, dry basis | F14: %TS | G14: ND | H14: 9.6e-05 | K14: 1.2e-08 | L14: 2.06e-05 | O14: 0 | P14: 9.6e-05 | S14: 1.2e-08 | T14: 9.6e-05 | W14: 1.2e-08 | X14: 0.00052 | AA14: 1.9836746e-09 | AB14: 0.00056 | AE14: 1e-10 | AF14: 0.002645129 | AI14: 5.3368057e-06 | AJ14: ref. 4 for NB2, NB5, and NB6, refs. 5-8 NB1, NB3, and NB4, and ref. 9 for RP
A15: 9 | B15: Feedstock Composition | C15: Feedstock Composition | D15: Cr_BM | E15: Cr content, dry basis | F15: %TS | G15: ND | H15: 0.00367 | K15: 3.0689167e-05 | L15: 0.00039 | O15: 6.8644e-06 | P15: 0.00367 | S15: 3.0689167e-05 | T15: 0.00367 | W15: 3.0689167e-05 | X15: 0.00073 | AA15: 1.089e-07 | AB15: 0.0062 | AE15: 4.84e-08 | AF15: 0.013896794 | AI15: 5.8778814e-05 | AJ15: ref. 4 for NB2, NB5, and NB6, refs. 5-8 NB1, NB3, and NB4, and ref. 9 for RP
A16: 10 | B16: Feedstock Composition | C16: Feedstock Composition | D16: Cu_BM | E16: Cu content, dry basis | F16: %TS | G16: ND | H16: 0.03 | K16: 0.00037719333 | L16: 0.007937 | O16: 1.21e-06 | P16: 0.03 | S16: 0.00037719333 | T16: 0.03 | W16: 0.00037719333 | X16: 5e-07 | AA16: 1.44e-06 | AB16: 0 | AE16: 7.2361e-06 | AF16: 0.0022031803 | AI16: 4.5617677e-06 | AJ16: ref. 4 for NB2, NB5, and NB6, refs. 5-8 NB1, NB3, and NB4, and ref. 9 for RP
A17: 11 | B17: Feedstock Composition | C17: Feedstock Composition | D17: Ni_BM | E17: Ni content, dry basis | F17: %TS | G17: ND | H17: 0.00249 | K17: 2.1104333e-06 | L17: 0.00461 | O17: 3.5721e-06 | P17: 0.00249 | S17: 2.1104333e-06 | T17: 0.00249 | W17: 2.1104333e-06 | X17: 0.00023 | AA17: 2.89e-08 | AB17: 0.00063 | AE17: 9e-10 | AF17: 0.0028055238 | AI17: 3.1591873e-06 | AJ17: ref. 4 for NB2, NB5, and NB6, refs. 5-8 NB1, NB3, and NB4, and ref. 9 for RP
A18: 12 | B18: Feedstock Composition | C18: Feedstock Composition | D18: Pb_BM | E18: Pb content, dry basis | F18: %TS | G18: ND | H18: 0.00372 | K18: 3.5312667e-06 | L18: 0.0002 | O18: 4.41e-08 | P18: 0.00372 | S18: 3.5312667e-06 | T18: 0.00372 | W18: 3.5312667e-06 | X18: 0.00026 | AA18: 1.6e-07 | AB18: 0.00041 | AE18: 6.3182117e-09 | AF18: 0.0014382381 | AI18: 2.2398541e-05 | AJ18: ref. 4 for NB2, NB5, and NB6, refs. 5-8 NB1, NB3, and NB4, and ref. 9 for RP
A19: 13 | B19: Feedstock Composition | C19: Feedstock Composition | D19: Zn_BM | E19: Zn content, dry basis | F19: %TS | G19: ND | H19: 0.07135 | K19: 0.00058962 | L19: 0.03999 | O19: 1.75561e-05 | P19: 0.07135 | S19: 0.00058962 | T19: 0.07135 | W19: 0.00058962 | X19: 0.00802 | AA19: 7.0225e-06 | AB19: 0.03496 | AE19: 1.225e-05 | AF19: 0.027012778 | AI19: 0.00064710085 | AJ19: ref. 4 for NB2, NB5, and NB6, refs. 5-8 NB1, NB3, and NB4, and ref. 9 for RP
A20: 14 | B20: Feedstock Composition | C20: Feedstock Composition | D20: CH4_pot_RAW | E20: Methane potential, raw biomass | F20: Nm3 CH4/t ww | G20: TD | H20: 20.475 | I20: 16.38 | J20: 24.57 | K20: 2.7948375 | L20: 180.26112 | M20: 144.2089 | N20: 216.31334 | O20: 216.62714 | P20: 20.475 | Q20: 16.38 | R20: 24.57 | S20: 2.7948375 | T20: 20.475 | U20: 16.38 | V20: 24.57 | W20: 2.7948375 | X20: 198.5175 | Y20: 158.814 | Z20: 238.221 | AA20: 262.72799 | AB20: 14.895 | AC20: 11.916 | AD20: 17.874 | AE20: 1.4790735 | AF20: 0 | AG20: 0 | AH20: 0 | AI20: 0 | AJ20: Assumed a range ±20% around default value
A21: 15 | B21: Storage | C21: Storage RAW biomass (Current-day feedstock - CF) | D21: CH4_storage_RAW | E21: CH4 emission | F21: % CH4 potential RAW | G21: TD | H21: 0 | I21: 0 | J21: 0 | K21: 0 | L21: 1 | M21: 0 | N21: 2 | O21: 0.16666667 | P21: 0 | Q21: 0 | R21: 0 | S21: 0 | T21: 0 | U21: 0 | V21: 0 | W21: 0 | X21: 0 | Y21: 0 | Z21: 0 | AA21: 0 | AB21: 5 | AC21: 0 | AD21: 17.2 | AE21: 13.046667 | AF21: 0 | AG21: 0 | AH21: 0 | AI21: 0 | AJ21: See Supplementary Information explanatory notes (section 4.8)
A22: 16 | B22: Storage | C22: Storage RAW biomass (Current-day feedstock - CF) | D22: N2O_storage_RAW | E22: N2O-N emission | F22: % N input RAW | G22: TD | H22: 0 | I22: 0 | J22: 0 | K22: 0 | L22: 0.45 | M22: 0 | N22: 1.7247449 | O22: 0.13339498 | P22: 0 | Q22: 0 | R22: 0 | S22: 0 | T22: 0 | U22: 0 | V22: 0 | W22: 0 | X22: 0 | Y22: 0 | Z22: 0 | AA22: 0 | AB22: 0 | AC22: 0 | AD22: 0 | AE22: 0 | AF22: 0 | AG22: 0 | AH22: 0 | AI22: 0 | AJ22: See Supplementary Information explanatory notes (section 4.8)
A23: 17 | B23: Storage | C23: Storage RAW biomass (Current-day feedstock - CF) | D23: NO_storage_RAW | E23: NOx-N emission | F23: % N input RAW | G23: TD | H23: 0 | I23: 0 | J23: 0 | K23: 0 | L23: 0 | M23: 0 | N23: 0 | O23: 0 | P23: 0 | Q23: 0 | R23: 0 | S23: 0 | T23: 0 | U23: 0 | V23: 0 | W23: 0 | X23: 0 | Y23: 0 | Z23: 0 | AA23: 0 | AB23: 0 | AC23: 0 | AD23: 0 | AE23: 0 | AF23: 0 | AG23: 0 | AH23: 0 | AI23: 0 | AJ23: See Supplementary Information explanatory notes (section 4.8)
A24: 18 | B24: Storage | C24: Storage RAW biomass (Current-day feedstock - CF) | D24: NH3_storage_RAW | E24: NH3-N emission | F24: % N input RAW | G24: TD | H24: 0 | I24: 0 | J24: 0 | K24: 0 | L24: 3.6 | M24: 2 | N24: 8 | O24: 1.6088889 | P24: 0 | Q24: 0 | R24: 0 | S24: 0 | T24: 0 | U24: 0 | V24: 0 | W24: 0 | X24: 0 | Y24: 0 | Z24: 0 | AA24: 0 | AB24: 0.43984962 | AC24: 0 | AD24: 0 | AE24: 0.010748205 | AF24: 0 | AG24: 0 | AH24: 0 | AI24: 0 | AJ24: See Supplementary Information explanatory notes (section 4.8)
A25: 19 | B25: Storage | C25: Storage liquid fraction (Current-day feedstock - CF and Advanced scenario - AP) | D25: CH4_storage_liquid_fraction | E25: CH4 emission | F25: % CH4 potential LIQ | G25: TD | H25: 0 | I25: 0 | J25: 0 | K25: 0 | L25: 0 | M25: 0 | N25: 0 | O25: 0 | P25: 0 | Q25: 0 | R25: 0 | S25: 0 | T25: 0 | U25: 0 | V25: 0 | W25: 0 | X25: 0 | Y25: 0 | Z25: 0 | AA25: 0 | AB25: 10.5 | AC25: 0 | AD25: 34.494897 | AE25: 52.108418 | AF25: 0 | AG25: 0 | AH25: 0 | AI25: 0 | AJ25: See Supplementary Information explanatory notes (section 4.8)
A26: 20 | B26: Storage | C26: Storage liquid fraction (Current-day feedstock - CF and Advanced scenario - AP) | D26: N2O_storage_liquid_fraction | E26: N2O-N emission | F26: % N input LIQ | G26: TD | H26: 0 | I26: 0 | J26: 0 | K26: 0 | L26: 0 | M26: 0 | N26: 0 | O26: 0 | P26: 0 | Q26: 0 | R26: 0 | S26: 0 | T26: 0 | U26: 0 | V26: 0 | W26: 0 | X26: 0 | Y26: 0 | Z26: 0 | AA26: 0 | AB26: 0 | AC26: 0 | AD26: 0 | AE26: 0 | AF26: 0 | AG26: 0 | AH26: 0 | AI26: 0 | AJ26: See Supplementary Information explanatory notes (section 4.8)
A27: 21 | B27: Storage | C27: Storage liquid fraction (Current-day feedstock - CF and Advanced scenario - AP) | D27: NO_storage_liquid_fraction | E27: NOx-N emission | F27: % N input LIQ | G27: TD | H27: 0 | I27: 0 | J27: 0 | K27: 0 | L27: 0 | M27: 0 | N27: 0 | O27: 0 | P27: 0 | Q27: 0 | R27: 0 | S27: 0 | T27: 0 | U27: 0 | V27: 0 | W27: 0 | X27: 0 | Y27: 0 | Z27: 0 | AA27: 0 | AB27: 0 | AC27: 0 | AD27: 0 | AE27: 0 | AF27: 0 | AG27: 0 | AH27: 0 | AI27: 0 | AJ27: See Supplementary Information explanatory notes (section 4.8)
A28: 22 | B28: Storage | C28: Storage liquid fraction (Current-day feedstock - CF and Advanced scenario - AP) | D28: NH3_storage_liquid_fraction | E28: NH3-N emission | F28: % N input LIQ | G28: TD | H28: 0 | I28: 0 | J28: 0 | K28: 0 | L28: 0 | M28: 0 | N28: 0 | O28: 0 | P28: 0 | Q28: 0 | R28: 0 | S28: 0 | T28: 0 | U28: 0 | V28: 0 | W28: 0 | X28: 0 | Y28: 0 | Z28: 0 | AA28: 0 | AB28: 0.40056629 | AC28: 0 | AD28: 1.3619254 | AE28: 0.081652928 | AF28: 0 | AG28: 0 | AH28: 0 | AI28: 0 | AJ28: See Supplementary Information explanatory notes (section 4.8)
A29: 23 | B29: Storage | C29: Storage digestate (advanced scenario - AP) | D29: CH4_storage_DIG_P_recovery | E29: CH4 emission | F29: % CH4 potential DIG P-recovery | G29: TD | H29: 5 | I29: 0 | J29: 17.247449 | K29: 13.124291 | L29: 0 | M29: 0 | N29: 0 | O29: 0 | P29: 0 | Q29: 0 | R29: 0 | S29: 0 | T29: 0 | U29: 0 | V29: 0 | W29: 0 | X29: 0 | Y29: 0 | Z29: 0 | AA29: 0 | AB29: 5 | AC29: 0 | AD29: 17.247449 | AE29: 13.124291 | AF29: 0 | AG29: 0 | AH29: 0 | AI29: 0 | AJ29: See Supplementary Information explanatory notes (section 4.8)
A30: 24 | B30: Storage | C30: Storage digestate (advanced scenario - AP) | D30: N2O_storage_DIG_P_recovery | E30: N2O-N emission | F30: % N input DIG P-recovery | G30: TD | H30: 0 | I30: 0 | J30: 0 | K30: 0 | L30: 0 | M30: 0 | N30: 0 | O30: 0 | P30: 0 | Q30: 0 | R30: 0 | S30: 0 | T30: 0 | U30: 0 | V30: 0 | W30: 0 | X30: 0 | Y30: 0 | Z30: 0 | AA30: 0 | AB30: 0 | AC30: 0 | AD30: 0 | AE30: 0 | AF30: 0 | AG30: 0 | AH30: 0 | AI30: 0 | AJ30: See Supplementary Information explanatory notes (section 4.8)
A31: 25 | B31: Storage | C31: Storage digestate (advanced scenario - AP) | D31: NO_storage_DIG_P_recovery | E31: NOx-N emission | F31: % N input DIG P-recovery | G31: TD | H31: 0 | I31: 0 | J31: 0 | K31: 0 | L31: 0 | M31: 0 | N31: 0 | O31: 0 | P31: 0 | Q31: 0 | R31: 0 | S31: 0 | T31: 0 | U31: 0 | V31: 0 | W31: 0 | X31: 0 | Y31: 0 | Z31: 0 | AA31: 0 | AB31: 0 | AC31: 0 | AD31: 0 | AE31: 0 | AF31: 0 | AG31: 0 | AH31: 0 | AI31: 0 | AJ31: See Supplementary Information explanatory notes (section 4.8)
... A47: 41 | B47: Use-on-Land | C47: UOL RAW biomass (Current-day feedstock - CF) | D47: P_stored_RAW | E47: P stored in soils | F47: % P applied RAW | G47: TD | H47: 0 | I47: 0 | J47: 0 | K47: 0 | L47: 0 | M47: 0 | N47: 38.53885 | O47: 82.513496 | P47: 0 | Q47: 0 | R47: 0 | S47: 0 | T47: 0 | U47: 0 | V47: 0 | W47: 0 | X47: 0 | Y47: 47 | Z47: 65 | AA47: 187.72222 | AB47: 0 | AC47: 0 | AD47: 0 | AE47: 0 | AF47: 0 | AG47: 0 | AH47: 0 | AI47: 0 | AJ47: See Supplementary Information explanatory notes (section 4.10)
A48: 42 | B48: Use-on-Land | C48: UOL RAW biomass (Current-day feedstock - CF) | D48: C_seq_RAW | E48: C sequestration over 100y | F48: % C applied | G48: TD | L48: 11 | M48: 8.2 | N48: 13 | O48: 0.96888889 | AJ48: See Supplementary Information explanatory notes (section 4.10)
A49: 43 | B49: NPK & other substitution | C49: UOL RAW biomass (Current-day feedstock - CF) | D49: N_fert_subst_RAW | E49: N substitution efficiency | F49: kg N/kg N applied RAW | G49: TD | H49: 0 | I49: 0 | J49: 0 | K49: 0 | L49: 0.80100653 | M49: 0.64080522 | N49: 0.96120783 | O49: 0.0042774097 | P49: 0 | Q49: 0 | R49: 0 | S49: 0 | T49: 0 | U49: 0 | V49: 0 | W49: 0 | X49: 0 | Y49: 0.4368 | Z49: 0.6552 | AA49: 0.01854944 | AB49: 0 | AC49: 0 | AD49: 0 | AE49: 0 | AF49: 0 | AG49: 0 | AH49: 0 | AI49: 0 | AJ49: See Supplementary Information explanatory notes (section 4.10)
A50: 44 | B50: NPK & other substitution | C50: UOL RAW biomass (Current-day feedstock - CF) | D50: P_fert_subst_RAW | E50: P substitution efficiency | F50: kg P/kg P applied RAW | G50: TD | H50: 0 | I50: 0 | J50: 0 | K50: 0 | L50: 0.28290167 | M50: 0.28290167 | N50: 0.28290167 | O50: 1.5419764e-18 | P50: 0 | Q50: 0 | R50: 0 | S50: 0 | T50: 0 | U50: 0 | V50: 0 | W50: 0 | X50: 0 | Y50: 0.3 | Z50: 0.5 | AA50: 0.010555556 | AB50: 0 | AC50: 0 | AD50: 0 | AE50: 0 | AF50: 0 | AG50: 0 | AH50: 0 | AI50: 0 | AJ50: See Supplementary Information explanatory notes (section 4.10)
A51: 45 | B51: NPK & other substitution | C51: UOL RAW biomass (Current-day feedstock - CF) | D51: K_fert_subst_RAW | E51: K substitution efficiency | F51: kg K/kg K applied RAW | G51: TD | H51: 0 | I51: 0 | J51: 0 | K51: 0 | L51: 0.69841047 | M51: 0.58 | N51: 0.88 | O51: 0.0038054388 | P51: 0 | Q51: 0 | R51: 0 | S51: 0 | T51: 0 | U51: 0 | V51: 0 | W51: 0 | X51: 0 | Y51: 0.58 | Z51: 0.88 | AA51: 0.033355556 | AB51: 0 | AC51: 0 | AD51: 0 | AE51: 0 | AF51: 0 | AG51: 0 | AH51: 0 | AI51: 0 | AJ51: See Supplementary Information explanatory notes (section 4.10)
A52: 46 | B52: Use-on-Land | C52: UOL Liquid Fraction (Current-day feedstock - CF and Advanced scenario - AP) | D52: N_LF | E52: N emission to water (SurfaceWater) | F52: % N applied Liq fract | G52: TD | H52: 0 | I52: 0 | J52: 0 | K52: 0 | L52: 0 | M52: 0 | N52: 0 | O52: 0 | P52: 0 | Q52: 0 | R52: 0 | S52: 0 | T52: 0 | U52: 0 | V52: 0 | W52: 0 | X52: 0 | Y52: 0 | Z52: 0 | AA52: 0 | AB52: 0.978 | AC52: 0.3 | AD52: 3 | AE52: 0.328838 | AF52: 0 | AG52: 0 | AH52: 0 | AI52: 0 | AJ52: See Supplementary Information explanatory notes (section 4.10)
A53: 47 | B53: Use-on-Land | C53: UOL Liquid Fraction (Current-day feedstock - CF and Advanced scenario - AP) | D53: N_LF_GW | E53: N emission to water (GroundWater) | F53: % N applied Liq fract | G53: TD | H53: 0 | I53: 0 | J53: 0 | K53: 0 | L53: 0 | M53: 0 | N53: 0 | O53: 0 | P53: 0 | Q53: 0 | R53: 0 | S53: 0 | T53: 0 | U53: 0 | V53: 0 | W53: 0 | X53: 0 | Y53: 0 | Z53: 0 | AA53: 0 | AB53: 12.362 | AC53: 0 | AD53: 27.298 | AE53: 31.141221 | AF53: 0 | AG53: 0 | AH53: 0 | AI53: 0 | AJ53: See Supplementary Information explanatory notes (section 4.10)
A54: 48 | B54: Use-on-Land | C54: UOL Liquid Fraction (Current-day feedstock - CF and Advanced scenario - AP) | D54: N2O_LF | E54: N2O-N emission | F54: % N applied Liq fract | G54: TD | H54: 0 | I54: 0 | J54: 0 | K54: 0 | L54: 0 | M54: 0 | N54: 0 | O54: 0 | P54: 0 | Q54: 0 | R54: 0 | S54: 0 | T54: 0 | U54: 0 | V54: 0 | W54: 0 | X54: 0 | Y54: 0 | Z54: 0 | AA54: 0 | AB54: 0.978 | AC54: 0.3 | AD54: 3 | AE54: 0.328838 | AF54: 0 | AG54: 0 | AH54: 0 | AI54: 0 | AJ54: See Supplementary Information explanatory notes (section 4.10)
A55: 49 | B55: Use-on-Land | C55: UOL Liquid Fraction (Current-day feedstock - CF and Advanced scenario - AP) | D55: NH3_LF | E55: NH3-N emission | F55: % N applied Liq fract | G55: TD | H55: 0 | I55: 0 | J55: 0 | K55: 0 | L55: 0 | M55: 0 | N55: 0 | O55: 0 | P55: 0 | Q55: 0 | R55: 0 | S55: 0 | T55: 0 | U55: 0 | V55: 0 | W55: 0 | X55: 0 | Y55: 0 | Z55: 0 | AA55: 0 | AB55: 0.978 | AC55: 0.3 | AD55: 3 | AE55: 0.328838 | AF55: 0 | AG55: 0 | AH55: 0 | AI55: 0 | AJ55: See Supplementary Information explanatory notes (section 4.10)
A56: 50 | B56: Use-on-Land | C56: UOL Liquid Fraction (Current-day feedstock - CF and Advanced scenario - AP) | D56: N_stored_LF | E56: N stored in soil | F56: % N applied Liq fract | G56: TD | H56: 0 | I56: 0 | J56: 0 | K56: 0 | L56: 0 | M56: 0 | N56: 0 | O56: 0 | P56: 0 | Q56: 0 | R56: 0 | S56: 0 | T56: 0 | U56: 0 | V56: 0 | W56: 0 | X56: 0 | Y56: 0 | Z56: 0 | AA56: 0 | AB56: 2.2 | AC56: 0.3 | AD56: 3 | AE56: 0.32055556 | AF56: 0 | AG56: 0 | AH56: 0 | AI56: 0 | AJ56: See Supplementary Information explanatory notes (section 4.10)
A57: 51 | B57: Use-on-Land | C57: UOL Liquid Fraction (Current-day feedstock - CF and Advanced scenario - AP) | D57: N_uptaken_LF | E57: N uptaken by plants | F57: % N applied Liq fract | G57: TD | H57: 0 | I57: 0 | J57: 0 | K57: 0 | L57: 0 | M57: 0 | N57: 0 | O57: 0 | P57: 0 | Q57: 0 | R57: 0 | S57: 0 | T57: 0 | U57: 0 | V57: 0 | W57: 0 | X57: 0 | Y57: 0 | Z57: 0 | AA57: 0 | AB57: 74.68 | AC57: 59.744 | AD57: 89.616 | AE57: 37.180683 | AF57: 0 | AG57: 0 | AH57: 0 | AI57: 0 | AJ57: See Supplementary Information explanatory notes (section 4.10)
A58: 52 | B58: Use-on-Land | C58: UOL Liquid Fraction (Current-day feedstock - CF and Advanced scenario - AP) | D58: N2_LF | E58: N released as N2 | F58: % N applied Liq fract | G58: TD | H58: 0 | I58: 0 | J58: 0 | K58: 0 | L58: 0 | M58: 0 | N58: 0 | O58: 0 | P58: 0 | Q58: 0 | R58: 0 | S58: 0 | T58: 0 | U58: 0 | V58: 0 | W58: 0 | X58: 0 | Y58: 0 | Z58: 0 | AA58: 0 | AB58: 7.824 | AC58: 6.2592 | AD58: 9.3888 | AE58: 0.40809984 | AF58: 0 | AG58: 0 | AH58: 0 | AI58: 0 | AJ58: See Supplementary Information explanatory notes (section 4.10)
...

Sheet Supplem.Table 3
A1: Process | B1: Sub-process | C1: Parameter name | D1: Description | E1: Unit | F1: Distribution
A2: Feedstock Composition | B2: Feedstock Composition | C2: N_BM | D2: N content, dry basis | E2: %TS | F2: ND
A3: Feedstock Composition | B3: Feedstock Composition | C3: P_BM | D3: P content, dry basis | E3: %TS | F3: ND
A4: Feedstock Composition | B4: Feedstock Composition | C4: K_BM | D4: K content, dry basis | E4: %TS | F4: ND
A5: Feedstock Composition | B5: Feedstock Composition | C5: Cbioand_BM | D5: C content, dry basis | E5: %TS | F5: ND
A6: Feedstock Composition | B6: Feedstock Composition | C6: Energy_BM | D6: Energy content, dry basis | E6: MJ kg-1 TS | F6: ND
A7: Feedstock Composition | B7: Feedstock Composition | C7: Hg_BM | D7: Hg content, dry basis | E7: %TS | F7: ND
A8: Feedstock Composition | B8: Feedstock Composition | C8: Cd_BM | D8: Cd content, dry basis | E8: %TS | F8: ND
A9: Feedstock Composition | B9: Feedstock Composition | C9: Cr_BM | D9: Cr content, dry basis | E9: %TS | F9: ND
A10: Feedstock Composition | B10: Feedstock Composition | C10: Cu_BM | D10: Cu content, dry basis | E10: %TS | F10: ND
A11: Feedstock Composition | B11: Feedstock Composition | C11: Ni_BM | D11: Ni content, dry basis | E11: %TS | F11: ND
A12: Feedstock Composition | B12: Feedstock Composition | C12: Pb_BM | D12: Pb content, dry basis | E12: %TS | F12: ND
... A31: Transport | B31: Transport | C31: Tr_OW | D31: km transport of RAW feedstock in the Advanced scenario - A | E31: km*kg ww | F31: TD

Sheet Supplem.Table 4
A1: Scenario | B1: CC | C1: TA | D1: ME-N | E1: FE-P | F1: POF | G1: PM | H1: HTc | I1: ET | J1: RDf | K1: TE | L1: HTnc | M1: IR | N1: OD | O1: Sum of Abs values
A2: NB1 | B2: -0.52 | C2: -0.02 | D2: 0 | E2: 45.25 | F2: -0.1 | G2: -0.77 | H2: -2.41 | I2: -0.46 | J2: -0.46 | K2: 0.19 | L2: -5.1 | M2: -0.07 | N2: -0.02 | O2: 55.35
A3: NB2 | B3: 1.76 | C3: -8.79 | D3: -19.3 | E3: -361.02 | F3: 1.74 | G3: 0.23 | H3: 3.27 | I3: 14.74 | J3: 1.21 | K3: -11.31 | L3: 446.7 | M3: 0.18 | N3: 0.03 | O3: 870.27
A4: NB3 | B4: -0.01 | C4: 0.02 | D4: 0 | E4: 50.59 | F4: 0.02 | G4: 0.09 | H4: 10.11 | I4: 93.62 | J4: 0.06 | K4: 0 | L4: 2221.55 | M4: -0.02 | N4: 0 | O4: 2376.07
A5: NB4 | B5: 0.01 | C5: -0.03 | D5: 0.01 | E5: 45.44 | F5: 0.03 | G5: -0.37 | H5: 0.48 | I5: 0.1 | J5: 0.05 | K5: -0.3 | L5: 3.99 | M5: 0.11 | N5: 0.09 | O5: 51.01
A6: NB5 | B6: -0.05 | C6: 1.08 | D6: 0.01 | E6: 45.5 | F6: 0.2 | G6: 0.69 | H6: 0.32 | I6: 6.44 | J6: -0.09 | K6: 0.08 | L6: 199.25 | M6: 0.02 | N6: 0 | O6: 253.72
A7: NB6 | B7: -2.82 | C7: -2.44 | D7: -10.66 | E7: -467 | F7: -5.21 | G7: 5.5 | H7: 9.42 | I7: 3.89 | J7: 5.96 | K7: -5.11 | L7: 75.88 | M7: 1.37 | N7: 0.11 | O7: 595.37
A8: RP | B8: 0.38 | C8: 1.38 | D8: 0.06 | E8: 45.92 | F8: 0.6 | G8: 1.74 | H8: 4.49 | I8: 6.17 | J8: 0.94 | K8: 0.36 | L8: 206.22 | M8: 0.28 | N8: 0.01 | O8: 268.56

Sheet Supplem.Table 5
A1: Scenario | B1: CC | C1: TA | D1: ME-N | E1: FE-P | F1: POF | G1: PM | H1: HTc | I1: ET | J1: RD,f | K1: TE | L1: HTnc | M1: IR | N1: OD | O1: Sum
A2: NB1 | B2: 0.009 | C2: 0 | D2: 0 | E2: 0.817 | F2: 0.002 | G2: 0.014 | H2: 0.044 | I2: 0.008 | J2: 0.008 | K2: 0.003 | L2: 0.092 | M2: 0.001 | N2: 0 | O2: 1
A3: NB2 | B3: 0.002 | C3: 0.01 | D3: 0.022 | E3: 0.415 | F3: 0.002 | G3: 0 | H3: 0.004 | I3: 0.017 | J3: 0.001 | K3: 0.013 | L3: 0.513 | M3: 0 | N3: 0 | O3: 1
A4: NB3 | B4: 0 | C4: 0 | D4: 0 | E4: 0.021 | F4: 0 | G4: 0 | H4: 0.004 | I4: 0.039 | J4: 0 | K4: 0 | L4: 0.935 | M4: 0 | N4: 0 | O4: 1
A5: NB4 | B5: 0 | C5: 0.001 | D5: 0 | E5: 0.891 | F5: 0.001 | G5: 0.007 | H5: 0.009 | I5: 0.002 | J5: 0.001 | K5: 0.006 | L5: 0.078 | M5: 0.002 | N5: 0.002 | O5: 1
A6: NB5 | B6: 0 | C6: 0.004 | D6: 0 | E6: 0.179 | F6: 0.001 | G6: 0.003 | H6: 0.001 | I6: 0.025 | J6: 0 | K6: 0 | L6: 0.785 | M6: 0 | N6: 0 | O6: 1
A7: NB6 | B7: 0.005 | C7: 0.004 | D7: 0.018 | E7: 0.784 | F7: 0.009 | G7: 0.009 | H7: 0.016 | I7: 0.007 | J7: 0.01 | K7: 0.009 | L7: 0.127 | M7: 0.002 | N7: 0 | O7: 1
A8: RP | B8: 0.001 | C8: 0.005 | D8: 0 | E8: 0.171 | F8: 0.002 | G8: 0.006 | H8: 0.017 | I8: 0.023 | J8: 0.004 | K8: 0.001 | L8: 0.768 | M8: 0.001 | N8: 0 | O8: 1

Sheet Supplem.Table 6
A1: Scenario | B1: CC | C1: TA | D1: ME-N | E1: FE-P | F1: POF | G1: PM | H1: HTc | I1: ET | J1: RDf | K1: TE | L1: HTnc | M1: IR | N1: OD | O1: Sum of Abs values
A2: NB1 | B2: -0.20717438 | C2: 0.60224632 | D2: -5.1772647 | E2: -33.066266 | F2: 0.38227325 | G2: 0.42303955 | H2: 0.093793223 | I2: 2.5715977 | J2: 0.3439371 | K2: 0.27104021 | L2: 92.238025 | M2: 0.09594906 | N2: -0.0029952846 | O2: 135.4756
A3: NB2 | B3: 1.5728334 | C3: -8.0668584 | D3: -22.993335 | E3: 39.575345 | F3: 2.0242983 | G3: 2.1444274 | H3: 6.0943346 | I3: 17.19569 | J3: 1.8395552 | K3: -11.221242 | L3: 527.23944 | M3: 0.3206613 | N3: 0.03825664 | O3: 640.32628
A4: NB3 | B4: 0.42795283 | C4: -0.34083223 | D4: -25.525482 | E4: 23.490283 | F4: 1.2280071 | G4: 2.2490505 | H4: -7.3835009 | I4: -29.087152 | J4: 1.9509857 | K4: -1.4033312 | L4: -571.95615 | M4: 0.26906765 | N4: 0.03658796 | O4: 665.34838
A5: NB4 | B5: 0.39867766 | C5: -0.35111167 | D5: -22.736316 | E5: 21.281232 | F5: 1.1121958 | G5: 1.5440148 | H5: -15.126182 | I5: -109.20635 | J5: 1.7314869 | K5: -1.560186 | L5: -2485.3751 | M5: 0.37289794 | N5: 0.1252203 | O5: 2660.921
A6: NB5 | B6: 1.3055793 | C6: 1.0972887 | D6: -34.720971 | E6: 19.03136 | F6: 1.9610413 | G6: 2.9513721 | H6: 3.1006858 | I6: 3.4997284 | J6: 1.8428581 | K6: -0.61651214 | L6: 95.97637 | M6: 0.020663154 | N6: 0.038466228 | O6: 166.1629
A7: NB6 | B7: -2.3758633 | C7: -1.8459618 | D7: -7.1560818 | E7: 30.302776 | F7: -4.9613442 | G7: 6.2443316 | H7: 11.336033 | I7: 6.544866 | J7: 6.3486182 | K7: -4.9631785 | L7: 164.60387 | M7: 1.373246 | N7: 0.11527261 | O7: 248.17144
A8: RP | B8: 0.38046579 | C8: 1.3836184 | D8: 0.057852241 | E8: 45.91701 | F8: 0.60319634 | G8: 1.7402639 | H8: 4.4915805 | I8: 6.1705054 | J8: 0.94243317 | K8: 0.36011557 | L8: 206.21777 | M8: 0.27954439 | N8: 0.013230928 | O8: 268.55759

Sheet Supplem.Table 7
A1: Scenario | B1: CC | C1: TA | D1: ME-N | E1: FE-P | F1: POF | G1: PM | H1: HTc | I1: ET | J1: RDf | K1: TE | L1: HTnc | M1: IR | N1: OD | O1: Sum
A2: NB1 | B2: =ABS('Supplem.Table 6'!B2)/'Supplem.Table 6'!$O2 -> 0.0015292376 | C2: =ABS('Supplem.Table 6'!C2)/'Supplem.Table 6'!$O2 -> 0.0044454228 | D2: =ABS('Supplem.Table 6'!D2)/'Supplem.Table 6'!$O2 -> 0.038215477 | E2: =ABS('Supplem.Table 6'!E2)/'Supplem.Table 6'!$O2 -> 0.24407543 | F2: =ABS('Supplem.Table 6'!F2)/'Supplem.Table 6'!$O2 -> 0.0028217129 | G2: =ABS('Supplem.Table 6'!G2)/'Supplem.Table 6'!$O2 -> 0.0031226254 | H2: =ABS('Supplem.Table 6'!H2)/'Supplem.Table 6'!$O2 -> 0.00069232557 | I2: =ABS('Supplem.Table 6'!I2)/'Supplem.Table 6'!$O2 -> 0.018981999 | ... O2: =ABS('Supplem.Table 6'!O2)/'Supplem.Table 6'!$O2 -> 1
A3: NB2 | B3: =ABS('Supplem.Table 6'!B3)/'Supplem.Table 6'!$O3 -> 0.0024562999 | C3: =ABS('Supplem.Table 6'!C3)/'Supplem.Table 6'!$O3 -> 0.012598044 | D3: =ABS('Supplem.Table 6'!D3)/'Supplem.Table 6'!$O3 -> 0.035908779 | E3: =ABS('Supplem.Table 6'!E3)/'Supplem.Table 6'!$O3 -> 0.061804967 | F3: =ABS('Supplem.Table 6'!F3)/'Supplem.Table 6'!$O3 -> 0.0031613543 | G3: =ABS('Supplem.Table 6'!G3)/'Supplem.Table 6'!$O3 -> 0.0033489605 | H3: =ABS('Supplem.Table 6'!H3)/'Supplem.Table 6'!$O3 -> 0.0095175458 | I3: =ABS('Supplem.Table 6'!I3)/'Supplem.Table 6'!$O3 -> 0.026854575 | ... O3: =ABS('Supplem.Table 6'!O3)/'Supplem.Table 6'!$O3 -> 1
A4: NB3 | B4: =ABS('Supplem.Table 6'!B4)/'Supplem.Table 6'!$O4 -> 0.00064320113 | C4: =ABS('Supplem.Table 6'!C4)/'Supplem.Table 6'!$O4 -> 0.00051226131 | D4: =ABS('Supplem.Table 6'!D4)/'Supplem.Table 6'!$O4 -> 0.038364086 | E4: =ABS('Supplem.Table 6'!E4)/'Supplem.Table 6'!$O4 -> 0.035305238 | F4: =ABS('Supplem.Table 6'!F4)/'Supplem.Table 6'!$O4 -> 0.0018456604 | G4: =ABS('Supplem.Table 6'!G4)/'Supplem.Table 6'!$O4 -> 0.0033802599 | H4: =ABS('Supplem.Table 6'!H4)/'Supplem.Table 6'!$O4 -> 0.011097195 | I4: =ABS('Supplem.Table 6'!I4)/'Supplem.Table 6'!$O4 -> 0.043717176 | ... O4: =ABS('Supplem.Table 6'!O4)/'Supplem.Table 6'!$O4 -> 1
A5: NB4 | B5: =ABS('Supplem.Table 6'!B5)/'Supplem.Table 6'!$O5 -> 0.00014982695 | C5: =ABS('Supplem.Table 6'!C5)/'Supplem.Table 6'!$O5 -> 0.00013195118 | D5: =ABS('Supplem.Table 6'!D5)/'Supplem.Table 6'!$O5 -> 0.0085445287 | E5: =ABS('Supplem.Table 6'!E5)/'Supplem.Table 6'!$O5 -> 0.0079976942 | F5: =ABS('Supplem.Table 6'!F5)/'Supplem.Table 6'!$O5 -> 0.00041797399 | G5: =ABS('Supplem.Table 6'!G5)/'Supplem.Table 6'!$O5 -> 0.0005802558 | H5: =ABS('Supplem.Table 6'!H5)/'Supplem.Table 6'!$O5 -> 0.0056845663 | I5: =ABS('Supplem.Table 6'!I5)/'Supplem.Table 6'!$O5 -> 0.041040808 | ... O5: =ABS('Supplem.Table 6'!O5)/'Supplem.Table 6'!$O5 -> 1
A6: NB5 | B6: =ABS('Supplem.Table 6'!B6)/'Supplem.Table 6'!$O6 -> 0.0078572249 | C6: =ABS('Supplem.Table 6'!C6)/'Supplem.Table 6'!$O6 -> 0.006603693 | D6: =ABS('Supplem.Table 6'!D6)/'Supplem.Table 6'!$O6 -> 0.20895743 | E6: =ABS('Supplem.Table 6'!E6)/'Supplem.Table 6'!$O6 -> 0.11453435 | F6: =ABS('Supplem.Table 6'!F6)/'Supplem.Table 6'!$O6 -> 0.011801921 | G6: =ABS('Supplem.Table 6'!G6)/'Supplem.Table 6'!$O6 -> 0.01776192 | H6: =ABS('Supplem.Table 6'!H6)/'Supplem.Table 6'!$O6 -> 0.018660518 | I6: =ABS('Supplem.Table 6'!I6)/'Supplem.Table 6'!$O6 -> 0.021062033 | ... O6: =ABS('Supplem.Table 6'!O6)/'Supplem.Table 6'!$O6 -> 1
A7: NB6 | B7: =ABS('Supplem.Table 6'!B7)/'Supplem.Table 6'!$O7 -> 0.0095734757 | C7: =ABS('Supplem.Table 6'!C7)/'Supplem.Table 6'!$O7 -> 0.0074382523 | D7: =ABS('Supplem.Table 6'!D7)/'Supplem.Table 6'!$O7 -> 0.028835234 | E7: =ABS('Supplem.Table 6'!E7)/'Supplem.Table 6'!$O7 -> 0.1221042 | F7: =ABS('Supplem.Table 6'!F7)/'Supplem.Table 6'!$O7 -> 0.0199916 | G7: =ABS('Supplem.Table 6'!G7)/'Supplem.Table 6'!$O7 -> 0.025161362 | H7: =ABS('Supplem.Table 6'!H7)/'Supplem.Table 6'!$O7 -> 0.045678231 | I7: =ABS('Supplem.Table 6'!I7)/'Supplem.Table 6'!$O7 -> 0.026372357 | ... O7: =ABS('Supplem.Table 6'!O7)/'Supplem.Table 6'!$O7 -> 1
A8: RP | B8: =ABS('Supplem.Table 6'!B8)/'Supplem.Table 6'!$O8 -> 0.0014167009 | C8: =ABS('Supplem.Table 6'!C8)/'Supplem.Table 6'!$O8 -> 0.0051520361 | D8: =ABS('Supplem.Table 6'!D8)/'Supplem.Table 6'!$O8 -> 0.00021541838 | E8: =ABS('Supplem.Table 6'!E8)/'Supplem.Table 6'!$O8 -> 0.1709764 | F8: =ABS('Supplem.Table 6'!F8)/'Supplem.Table 6'!$O8 -> 0.0022460596 | G8: =ABS('Supplem.Table 6'!G8)/'Supplem.Table 6'!$O8 -> 0.0064800402 | H8: =ABS('Supplem.Table 6'!H8)/'Supplem.Table 6'!$O8 -> 0.016724832 | I8: =ABS('Supplem.Table 6'!I8)/'Supplem.Table 6'!$O8 -> 0.02297647 | ... O8: =ABS('Supplem.Table 6'!O8)/'Supplem.Table 6'!$O8 -> 1

Sheet Supplem.Table 8
A1: Scenario | B1: Functional unit | D1: Type of input material applied | E1: Total weight of input material applied (kg) | F1: Type of concentrated P-fertiliser | G1: P concentration of concentrated P-fertiliser (% dry matter) | H1: Bio-available P fraction of concentrated P-fertiliser (% of total P) | I1: P-recovery in concentrated P-fertiliser (% of P in input material)*
A2: AP1 | B2: 1 kg bio-available P in a concentrated P-fertiliser | D2: undigested sewage sludge (5% DM) | E2: 1772 | F2: struvite | G2: 12.6 | H2: 100 | I2: 46
A3: AP2 | D3: raw poultry litter (48% DM) | E3: 139 | F3: poultry litter ash | G3: 6.5 | H3: 93 | I3: 100
A4: AP3 | D4: undigested sewage sludge (5% DM) | E4: 925 | F4: AshDec® rhenanite-like substance | G4: 7.4 | H4: 90 | I4: 98
A5: AP4 | D5: undigested sewage sludge (5% DM) | E5: 824 | F5: phosphoric acid | G5: 31.6 | H5: 100 | I5: 100
A6: AP5 | D6: meat-and-bone meal (97% DM) | E6: 31 | F6: single superphosphate-like material | G6: 8.7 | H6: 100 | I6: 100
A7: AP6 | D7: raw pig manure (slurry, 5% DM) | E7: 3565 | F7: pyrolysis material | G7: 4.2 | H7: 85 | I7: 62
A8: RP | D8: rock phosphate (100% DM) | E8: 7.41 | F8: single superphosphate | G8: 7.9 | H8: 100 | I8: 100
A9: *physical P-losses and spills are assumed to be zero across all pathways

Sheet Supplem.Table 9
A1: Property | B1: Unit | C1: SEW | D1: SEW | E1: POM | F1: MBM | G1: PIM | H1: PIM | I1: PIM
C2: (thick) | D2: (dg dw) | E2: (raw) | F2: (raw) | G2: (raw) | H2: (dw) | I2: (cp)
A3: Water | B3: %ww | C3: 95 | D3: 75 | E3: 44.8 | F3: 2.9 | G3: 95 | H3: 75 | I3: 60
A4: TS | B4: %ww | C4: 5 | D4: 25 | E4: 55.2 | F4: 97.1 | G4: 5 | H4: 25 | I4: 40
A5: VS | B5: %TS | C5: 75 | D5: 57.5 | E5: 78.5 | F5: 66.6 | G5: 66.2 | H5: 72 | I5: 43
A6: Ash | B6: %TS | C6: 25 | D6: 42.5 | E6: 21.5 | F6: 33.4 | G6: 33.8 | H6: 28 | I6: 57
A7: LHVdb | B7: MJ kg-1 TS | C7: 18.8 | D7: 13.5 | E7: 15.3 | F7: 10.1 | G7: 18.8 | H7: 21 | I7: 13
A8: LHVwb | B8: MJ kg-1 ww | C8: -1.4 | D8: 1.54 | E8: 7.35 | F8: 9.74 | G8: 2.9 | H8: 3.3 | I8: 3.7
A9: CH4 pot | B9: NL kg-1 VS | C9: 546 | D9: nr | E9: 416 | F9: 519 | G9: 450 | H9: 450 | I9: nr
A10: C | B10: %TS | C10: 40 | D10: 35 | E10: 39 | F10: 39 | G10: 35 | H10: 41 | I10: 26
A11: K | B11: %TS | C11: 0.3 | D11: 0.56 | E11: 2.5 | F11: 0.57 | G11: 1.6 | H11: 0.73 | I11: 1.1
A12: N | B12: %TS | C12: 4.4 | D12: 9.3 | E12: 4.2 | F12: 9.1 | G12: 5 | H12: 2.7 | I12: 3
A13: P | B13: %TS | C13: 2.5 | D13: 5.2 | E13: 1.4 | F13: 3.3 | G13: 1.1 | H13: 1.2 | I13: 1.9
A14: As | B14: %TS | C14: 0.0004 | D14: 0.00085 | E14: 3.6e-05 | F14: 0 | G14: 0.00021 | H14: 0.00034 | I14: 0.00054
A15: Cd | B15: %TS | C15: 9.6e-05 | D15: 0.0002 | E15: 2.1e-05 | F15: 5e-05 | G15: 2e-05 | H15: 1.1e-05 | I15: 1.7e-05
A16: Cr | B16: %TS | C16: 0.0037 | D16: 0.0078 | E16: 0.00039 | F16: 0.00052 | G16: 0.00056 | H16: 0.00033 | I16: 0.00052
A17: Cu | B17: %TS | C17: 0.03 | D17: 0.064 | E17: 0.0079 | F17: 0.00073 | G17: 0.0062 | H17: 0.0068 | I17: 0.011
A18: Hg | B18: %TS | C18: 5.9e-05 | D18: 0.00013 | E18: 0 | F18: 5e-07 | G18: 0 | H18: 0 | I18: 0
A19: Ni | B19: %TS | C19: 0.0025 | D19: 0.0053 | E19: 0.0046 | F19: 0.00023 | G19: 0.00063 | H19: 6.5e-05 | I19: 0.0001
A20: Pb | B20: %TS | C20: 0.0037 | D20: 0.0079 | E20: 0.0002 | F20: 0.00026 | G20: 0.00041 | H20: 0.0003 | I20: 0.00047
A21: Zn | B21: %TS | C21: 0.071 | D21: 0.15 | E21: 0.04 | F21: 0.008 | G21: 0.035 | H21: 0.027 | I21: 0.043

Sheet Supplem.Table 10
C1: Concentrated P-fertilisers
C2: AP1 | D2: AP2 | E2: AP3 | F2: AP4 | G2: AP5 | H2: AP6 | I2: RP
A3: C | B3: %TS | C3: 0.1 | D3: 1.0871933 | E3: <1 | F3: 0 | G3: 0 | H3: 32.807273 | I3: na
A4: K | B4: %TS | C4: 0 | D4: 11.571703 | E4: 0.81064034 | F4: 0 | G4: 1.7013182 | H4: 2.5138039 | I4: na
A5: N | B5: %TS | C5: 5.7 | D5: 0 | E5: 0 | F5: 0 | G5: 0 | H5: 2.9612547 | I5: na
A6: P | B6: %TS | C6: 12.6 | D6: 6.4972079 | E6: 7.4005606 | F6: 31.632653 | G6: 8.7 | H6: 4.1529671 | I6: 7.9
A7: As | B7: mg kg-1 TS | C7: <1 | D7: 1.6420775 | E7: 4 | F7: <1 | G7: <1 | H7: 11.836694 | I7: 7.430332
A8: Cd | B8: mg kg-1 TS | C8: <1 | D8: 0.95429594 | E8: 0.37 | F8: <1 | G8: 1.6472941 | H8: <1 | I8: 26.833466
A9: Cr | B9: mg kg-1 TS | C9: <1 | D9: 18.058219 | E9: 127 | F9: 5 | G9: 18.031247 | H9: 11.556407 | I9: 141.51653
A10: Cu | B10: mg kg-1 TS | C10: <1 | D10: 366.03812 | E10: 601 | F10: 5 | G10: 23.587889 | H10: 235.84659 | I10: 49.700571
A11: Hg | B11: mg kg-1 TS | C11: <1 | D11: 0 | E11: 0.7 | F11: <1 | G11: <1 | H11: <1 | I11: <1
A12: Ni | B12: mg kg-1 TS | C12: <1 | D12: 213.38178 | E12: 56 | F12: <1 | G12: 7.5669309 | H12: 2.2609225 | I12: 27.810548
A13: Pb | B13: mg kg-1 TS | C13: <1 | D13: 9.2463137 | E13: 59.8 | F13: <1 | G13: 8.187884 | H13: 10.399368 | I13: 13.326253
A14: Zn | B14: mg kg-1 TS | C14: 2 | D14: 284.98527 | E14: 1737 | F14: 3 | G14: 265.30661 | H14: 936.79233 | I14: 250

Sheet Supplem.Table 11
C1: NB1 | E1: NB2 | G1: NB3 | I1: NB4 | K1: NB5 | M1: NB6 | O1: RP
C2: AP1 | D2: CF1 | E2: AP2 | F2: CF2 | G2: AP3 | H2: CF3 | I2: AP4 | J2: CF4 | K2: AP5 | L2: CF5 | M2: AP6 | N2: CF6
A3: Functional Unit
A4: P-fertilizer bioav. | B4: kg P | C4: 1 | E4: 1 | G4: 1 | I4: 1 | K4: 1 | M4: 1 | O4: 1
A5: Inputs
A6: Input-feedstock | B6: kg ww | C6: 1772 | D6: 1772 | E6: 139 | F6: 139 | G6: 926 | H6: 926 | I6: 824 | J6: 824 | K6: 31 | L6: 31 | M6: 3571 | N6: 3571 | O6: 7.41
A7: Input-feedstock | B7: kg TS | C7: 89 | D7: 89 | E7: 67 | F7: 67 | G7: 46 | H7: 46 | I7: 41 | J7: 41 | K7: 30 | L7: 30 | M7: 179 | N7: 179 | O7: 7.41
A8: Input-P | B8: kg P | C8: 2.17 | D8: 2.17 | E8: 1.07 | F8: 1.07 | G8: 1.13 | H8: 1.13 | I8: 1.01 | J8: 1.01 | K8: 1 | L8: 1 | M8: 2.07 | N8: 2.07 | O8: 1
A9: Electricity | B9: kWh | C9: 19.8 | D9: 24.4 | E9: 12.8 | F9: 0 | G9: 13.8 | H9: 12.77 | I9: 11.8 | J9: 11.4 | K9: 2.9 | L9: 2.1 | M9: 29.5 | N9: 13.4 | O9: 1.6
A10: Outputs
A11: Electricity | B11: kWh | C11: 85.8 | D11: 88.5 | E11: 85.1 | F11: 0 | G11: 46.3 | H11: 46.3 | I11: 41.2 | J11: 41.2 | K11: 11.9 | L11: 11.9 | M11: 0 | N11: 122 | O11: 0
A12: P (other flows) | B12: kg P | C12: 0 | D12: 0 | E12: 0 | F12: 1.1 | G12: 0 | H12: 0 | I12: 0 | J12: 0 | K12: 0 | L12: 0 | M12: 0.71428571 | N12: 1.8921429 | O12: 0
A13: N | B13: kg N | C13: 0.4 | D13: 0 | E13: 0 | F13: 3.1 | G13: 0 | H13: 0 | I13: 0 | J13: 0 | K13: 0 | L13: 0 | M13: 7.0403571 | N13: 8.8507143 | O13: 0
A14: K | B14: kg K | C14: 0 | D14: 0 | E14: 1.9 | F14: 1.9 | G14: 0.1 | H14: 0 | I14: 0.1 | J14: 0 | K14: 1.7 | L14: 0 | M14: 2.8528571 | N14: 2.8528571 | O14: 0
A15: C | B15: kg C | C15: 1.8 | D15: 0 | E15: 0 | F15: 29.6 | G15: 0 | H15: 0 | I15: 0 | J15: 0 | K15: 0 | L15: 0 | M15: 31.085714 | N15: 36.607143 | O15: 0
A16: Waste | B16: kg TS | C16: 15 | D16: 17.7 | E16: 0 | F16: 0 | G16: 0.01 | H16: 9.3 | I16: 0.01 | J16: 8.3 | K16: 0.02 | L16: 10.2 | M16: 0 | N16: 0 | O16: 0.001
A17: Avoided products
A18: Electricity | B18: kWh | C18: 85.8 | D18: 88.5 | E18: 85.1 | F18: 0 | G18: 46.3 | H18: 46.3 | I18: 41.2 | J18: 41.2 | K18: 11.9 | L18: 11.9 | M18: 0 | N18: 122 | O18: 0
A19: P (mineral) | B19: kg P | C19: 0 | D19: 0 | E19: 0 | F19: 0.3 | G19: 0 | H19: 0 | I19: 0 | J19: 0 | K19: 0 | L19: 0 | M19: 0.63235122 | N19: 0.81312609 | O19: 0
A20: N (mineral) | B20: kg N | C20: 0.4 | D20: 0 | E20: 0 | F20: 2.5 | G20: 0 | H20: 0 | I20: 0 | J20: 0 | K20: 0 | L20: 0 | M20: 5.8717357 | N20: 8.2621418 | O20: 0
A21: K (mineral) | B21: kg K | C21: 0 | D21: 0 | E21: 1.9 | F21: 1.3 | G21: 0.1 | H21: 0 | I21: 0.1 | J21: 0 | K21: 1.3 | L21: 0 | M21: 2.5190325 | N21: 2.6601929 | O21: 0

Sheet Supplem.Table 12
C1: NB1 | E1: NB2 | G1: NB3 | I1: NB4 | K1: NB5 | M1: NB6 | O1: RP
C2: AP1 | D2: CF1 | E2: AP2 | F2: CF2 | G2: AP3 | H2: CF3 | I2: AP4 | J2: CF4 | K2: AP5 | L2: CF5 | M2: AP6 | N2: CF6
A3: Functional Unit
A4: P-fertilizer bioav. | B4: kg P | C4: 1 | E4: 1 | G4: 1 | I4: 1 | K4: 1 | M4: 1 | O4: 1
A5: Inputs
A6: Input-feedstock | B6: kg ww | C6: 1772 | D6: 1772 | E6: 139 | F6: 139 | G6: 926 | H6: 926 | I6: 824 | J6: 824 | K6: 31 | L6: 31 | M6: 3571 | N6: 3571 | O6: 7.41
A7: Input-feedstock | B7: kg TS | C7: 89 | D7: 89 | E7: 67 | F7: 67 | G7: 46 | H7: 46 | I7: 41 | J7: 41 | K7: 30 | L7: 30 | M7: 179 | N7: 179 | O7: 7.41
A8: Input-P | B8: kg P | C8: 2.17 | D8: 2.17 | E8: 1.07 | F8: 1.07 | G8: 1.13 | H8: 1.13 | I8: 1.01 | J8: 1.01 | K8: 1 | L8: 1 | M8: 2.07 | N8: 2.07 | O8: 1
A9: Electricity | B9: kWh | C9: 9.5 | D9: 13.5 | E9: 12.8 | F9: 0 | G9: 13.8 | H9: 7.1 | I9: 11.8 | J9: 6.3 | K9: 2.9 | L9: 0 | M9: 29.5 | N9: 13.4 | O9: 1.6
A10: Outputs
A11: Electricity | B11: kWh | C11: 73.4 | D11: 77.3 | E11: 85.1 | F11: 6.9 | G11: 46.3 | H11: 40.4 | I11: 41.2 | J11: 35.9 | K11: 0 | L11: 0 | M11: 0 | N11: 122.02976 | O11: 0
A12: P (other flows) | B12: kg P | C12: 1.2 | D12: 2.2 | E12: 0 | F12: 1.1 | G12: 0 | H12: 1.1 | I12: 0 | J12: 1 | K12: 0 | L12: 1 | M12: 0.71428571 | N12: 1.8921429 | O12: 0
A13: N | B13: kg N | C13: 3.9 | D13: 3.9 | E13: 0 | F13: 3.1 | G13: 0 | H13: 2 | I13: 0 | J13: 1.8 | K13: 0 | L13: 2.8 | M13: 7.0403571 | N13: 8.8507143 | O13: 0
A14: K | B14: kg K | C14: 0.2 | D14: 0.2 | E14: 1.9 | F14: 1.9 | G14: 0.1 | H14: 0.1 | I14: 0.1 | J14: 0.1 | K14: 1.7 | L14: 1.7 | M14: 2.8528571 | N14: 2.8528571 | O14: 0
A15: C | B15: kg C | C15: 15.6 | D15: 14.5 | E15: 0 | F15: 29.6 | G15: 0 | H15: 7.6 | I15: 0 | J15: 6.8 | K15: 0 | L15: 11.8 | M15: 31.085714 | N15: 36.607143 | O15: 0
A16: Waste | B16: kg TS | C16: 0 | D16: 0 | E16: 0 | F16: 0 | G16: 0.01 | H16: 0 | I16: 0.01 | J16: 0 | K16: 0.02 | L16: 0 | M16: 0 | N16: 0 | O16: 0.001
A17: Avoided products
A18: Electricity | B18: kWh | C18: 73.4 | D18: 77.3 | E18: 85.1 | F18: 0 | G18: 46.3 | H18: 40.4 | I18: 41.2 | J18: 35.9 | K18: 0 | L18: 0 | M18: 0 | N18: 122.02976 | O18: 0
A19: P (mineral) | B19: kg P | C19: 0.5 | D19: 1 | E19: 0 | F19: 0.9 | G19: 0 | H19: 0.5 | I19: 0 | J19: 0.5 | K19: 0 | L19: 0.4 | M19: 0.71428571 | N19: 1.3289203 | O19: 0
A20: N (mineral) | B20: kg N | C20: 3.9 | D20: 3.9 | E20: 0 | F20: 3.1 | G20: 0 | H20: 2 | I20: 0 | J20: 1.8 | K20: 0 | L20: 2.8 | M20: 5.8717357 | N20: 8.2621418 | O20: 0
A21: K (mineral) | B21: kg K | C21: 0.2 | D21: 0.2 | E21: 1.9 | F21: 1.9 | G21: 0.1 | H21: 0.1 | I21: 0.1 | J21: 0.1 | K21: 1.7 | L21: 1.7 | M21: 2.6601929 | N21: 2.6601929 | O21: 0

Sheet Supplem.Table 13
B1: NB1 | C1: AP1 | G1: CF1
B2: Input (kg) | C2: P-fertiliser | D2: OFM | E2: Waste | F2: Air | G2: P-fertiliser | H2: OFM | I2: Waste | J2: Air
A3: P | B3: 2.2 | C3: 0.461 | D3: 0 | E3: 0.539 | F3: 0 | G3: 0 | H3: 0 | I3: 1 | J3: 0
A4: N | B4: 3.9 | C4: 0.106 | D4: 0 | E4: 0.894 | F4: 0 | G4: 0 | H4: 0 | I4: 0 | J4: 1
A5: K | B5: 0.23 | C5: 0.007 | D5: 0 | E5: 0.993 | F5: 0 | G5: 0 | H5: 0 | I5: 1 | J5: 0
A6: C | B6: 36 | C6: 0.051 | D6: 0 | E6: 0 | F6: 0.948 | G6: 0 | H6: 0 | I6: 0 | J6: 1
A7: As | B7: 0.00035 | C7: 0 | D7: 0 | E7: 0.995 | F7: 0.005 | G7: 0 | H7: 0 | I7: 1 | J7: 0
A8: Hg | B8: 5.2e-05 | C8: 0 | D8: 0 | E8: 0.992 | F8: 0.008 | G8: 0 | H8: 0 | I8: 1 | J8: 0
A9: Cd | B9: 8.5e-05 | C9: 0.002 | D9: 0 | E9: 0.997 | F9: 0 | G9: 0 | H9: 0 | I9: 1 | J9: 0
A10: Cr | B10: 0.0033 | C10: 0 | D10: 0 | E10: 0.999 | F10: 0.001 | G10: 0 | H10: 0 | I10: 1 | J10: 0
A11: Cu | B11: 0.027 | C11: 0 | D11: 0 | E11: 1 | F11: 0 | G11: 0 | H11: 0 | I11: 1 | J11: 0
A12: Ni | B12: 0.0022 | C12: 0 | D12: 0 | E12: 0.999 | F12: 0.001 | G12: 0 | H12: 0 | I12: 1 | J12: 0
A13: Pb | B13: 0.0033 | C13: 0 | D13: 0 | E13: 0.998 | F13: 0.002 | G13: 0 | H13: 0 | I13: 1 | J13: 0
A14: Zn | B14: 0.063 | C14: 0 | D14: 0 | E14: 0.999 | F14: 0.001 | G14: 0 | H14: 0 | I14: 1 | J14: 0
B15: NB2 | C15: AP2 | G15: CF2
B16: Input (kg) | C16: P-fertiliser | D16: OFM | E16: Waste | F16: Air | G16: P-fertiliser | H16: OFM | I16: Waste | J16: Air
A17: P | B17: 1.1 | C17: 1 | D17: 0 | E17: 0 | F17: 0 | G17: 0 | H17: 1 | I17: 0 | J17: 0
A18: N | B18: 3.2 | C18: 0 | D18: 0 | E18: 0 | F18: 1 | G18: 0 | H18: 0.96 | I18: 0 | J18: 0.041
A19: K | B19: 1.9 | C19: 1 | D19: 0 | E19: 0 | F19: 0 | G19: 0 | H19: 1 | I19: 0 | J19: 0
A20: C | B20: 30 | C20: 0.006 | D20: 0 | E20: 0 | F20: 0.994 | G20: 0 | H20: 0.988 | I20: 0 | J20: 0.012
A21: As | B21: 2.7e-05 | C21: 0.991 | D21: 0 | E21: 0 | F21: 0.009 | G21: 0 | H21: 1 | I21: 0 | J21: 0
A22: Hg | B22: 0 | C22: 0 | D22: 0 | E22: 0 | F22: 0 | G22: 0 | H22: 0 | I22: 0 | J22: 0
A23: Cd | B23: 1.6e-05 | C23: 0.999 | D23: 0 | E23: 0 | F23: 0.001 | G23: 0 | H23: 1 | I23: 0 | J23: 0
A24: Cr | B24: 0.0003 | C24: 0.999 | D24: 0 | E24: 0 | F24: 0.001 | G24: 0 | H24: 1 | I24: 0 | J24: 0
A25: Cu | B25: 0.0061 | C25: 1 | D25: 0 | E25: 0 | F25: 0 | G25: 0 | H25: 1 | I25: 0 | J25: 0
A26: Ni | B26: 0.0035 | C26: 0.998 | D26: 0 | E26: 0 | F26: 0.002 | G26: 0 | H26: 1 | I26: 0 | J26: 0
A27: Pb | B27: 0.00015 | C27: 0.995 | D27: 0 | E27: 0 | F27: 0.005 | G27: 0 | H27: 1 | I27: 0 | J27: 0
A28: Zn | B28: 0.031 | C28: 0.999 | D28: 0 | E28: 0 | F28: 0.001 | G28: 0 | H28: 1 | I28: 0 | J28: 0
B29: NB3 | C29: AP3 | G29: CF3
B30: Input (kg) | C30: P-fertiliser | D30: OFM | E30: Waste | F30: Air | G30: P-fertiliser | H30: OFM | I30: Waste | J30: Air
A31: P | B31: 1.1 | C31: 0.98 | D31: 0 | E31: 0.02 | F31: 0 | G31: 0 | H31: 0 | I31: 1 | J31: 0
A32: N | B32: 2 | C32: 0 | D32: 0 | E32: 0 | F32: 1 | G32: 0 | H32: 0 | I32: 0 | J32: 1
A33: K | B33: 0.12 | C33: 1 | D33: 0 | E33: 0 | F33: 0 | G33: 0 | H33: 0 | I33: 1 | J33: 0
A34: C | B34: 19 | C34: 0 | D34: 0 | E34: 0 | F34: 1 | G34: 0 | H34: 0 | I34: 0 | J34: 1
A35: As | B35: 0.00019 | C35: 0.323 | D35: 0 | E35: 0.668 | F35: 0.009 | G35: 0 | H35: 0 | I35: 1 | J35: 0
A36: Hg | B36: 2.7e-05 | C36: 0.384 | D36: 0 | E36: 0.606 | F36: 0.009 | G36: 0 | H36: 0 | I36: 1 | J36: 0
A37: Cd | B37: 4.4e-05 | C37: 0.125 | D37: 0 | E37: 0.874 | F37: 0.001 | G37: 0 | H37: 0 | I37: 1 | J37: 0
A38: Cr | B38: 0.0017 | C38: 0.999 | D38: 0 | E38: 0 | F38: 0.001 | G38: 0 | H38: 0 | I38: 1 | J38: 0
A39: Cu | B39: 0.014 | C39: 0.65 | D39: 0 | E39: 0.35 | F39: 0 | G39: 0 | H39: 0 | I39: 1 | J39: 0
A40: Ni | B40: 0.0012 | C40: 0.73 | D40: 0 | E40: 0.269 | F40: 0.001 | G40: 0 | H40: 0 | I40: 1 | J40: 0
...

Sheet Supplem.Table 14
B1: Unit | C1: MO-INC | D1: MO-INC | E1: MO-INC | F1: MO-PYR | G1: CO-INC
C2: SEW | D2: POM | E2: MBM | F2: PIM | G2: SEW
A3: Capacity
A4: Annual usage rate | B4: t a-1 | C4: 387500 | D4: 440000 | E4: 109500 | F4: 5998 | G4: 300000
A5: Life time | B5: a | C5: 20 | D5: 20 | E5: 20 | F5: 20 | G5: 20
A7: Inputs
A8: Feedstock-type | C8: SEW | D8: POM | E8: MBM | F8: PIM | G8: SEW
C9: (dg dw) | D9: (raw) | E9: (raw) | F9: (cp) | G9: (dg dw)
A10: Feedstock-quantity | B10: t | C10: 1 | D10: 1 | E10: 1 | F10: 1 | G10: 1
A11: Feedstock-energy | B11: MJ | C11: 1540 | D11: 7350 | E11: 9740 | F11: 3700 | G11: 1540
A12: Activated carbon | B12: kg t-1 | C12: 0 | D12: 0 | E12: 0 | F12: 0 | G12: 0.001
A13: CaOH2 | B13: kg t-1 | C13: 0 | D13: 0 | E13: 0 | F13: 0 | G13: 0.0057
A14: CaCO3 | B14: kg t-1 | C14: 0 | D14: 0 | E14: 0 | F14: 0 | G14: 0
A15: CaO3 | B15: kg t-1 | C15: 0 | D15: 2.3256 | E15: 0 | F15: 10.6475 | G15: 0.0003
A16: Diesel | B16: kg t-1 | C16: 0 | D16: 0.8546 | E16: 0 | F16: 0 | G16: 0
A17: Electricity | B17: kWh t-1 | C17: 66 | D17: 81 | E17: 66 | F17: 100 | G17: 70
A18: H2SO4 | B18: kg t-1 | C18: 0 | D18: 0.4803 | E18: 0 | F18: 0 | G18: 0
A19: HCl | B19: kg t-1 | C19: 0 | D19: 0 | E19: 0 | F19: 0 | G19: 5.6e-06
A20: Heavy fuel oil | B20: MJ t-1 | C20: 0 | D20: 0 | E20: 0 | F20: 1.1511 | G20: 0
A21: Lubricant oil | B21: kg t-1 | C21: 0 | D21: 0.0027 | E21: 0 | F21: 0 | G21: 0
... A28: Labour | B28: manh t-1 | C28: 0.33 | D28: 0.29 | E28: 0.48 | F28: 0.7 | G28: 0.42
A30: Outputs
A31: Ashes | B31: kg t-1 | C31: 10 | D31: 119 | E31: 325 | F31: 7.5 | G31: 10
A32: Electricity | B32: kWh t-1 | C32: 67α | D32: 613β | E32: 379γ | F32: 0δ | G32: 67ε
A34: Air emissions
A35: As | B35: kg t-1 | C35: 1e-05 | D35: 8.1e-07 | E35: 0 | F35: 1e-05 | G35: 1e-05
A36: Cd | B36: kg t-1 | C36: 2e-07 | D36: 4e-08 | E36: 1.9e-07 | F36: 2.7e-08 | G36: 2e-07
A37: CO | B37: kg t-1 | C37: 0.0069 | D37: 0.026 | E37: 0.15 | F37: 0 | G37: 0.033
A38: CO2 biogenic | B38: kg t-1 | C38: 320 | D38: 690 | E38: 1400 | F38: 160 | G38: 320
A39: Cr | B39: kg t-1 | C39: 1.6e-05 | D39: 1.5e-06 | E39: 4e-06 | F39: 1.7e-06 | G39: 1.6e-05
A40: Cu | B40: kg t-1 | C40: 3.2e-05 | D40: 7.6e-06 | E40: 1.4e-06 | F40: 8.8e-06 | G40: 3.2e-05
A41: Dioxins | B41: kg t-1 | C41: 1.8e-11 | D41: 1.8e-11 | E41: 1.8e-11 | F41: 1.8e-11 | G41: 1.8e-11
A42: Dust | B42: kg t-1 | C42: 0.0015 | D42: 0.001 | E42: 0.017 | F42: 6.6e-05 | G42: 0.003
A43: HCl | B43: kg t-1 | C43: 0.00074 | D43: 0 | E43: 0 | F43: 0.054 | G43: 0.0053
A44: HF | B44: kg t-1 | C44: 0 | D44: 0.00063 | E44: 0.0025 | F44: 0 | G44: 0.00039
A45: Hg | B45: kg t-1 | C45: 2.6e-06 | D45: 0 | E45: 4.1e-08 | F45: 0 | G45: 2.6e-06
A46: N2O | B46: kg t-1 | C46: 0.26 | D46: 0 | E46: 0 | F46: 0 | G46: 0
... A52: Zn | B52: kg t-1 | C52: 0 | D52: 0 | E52: 0 | F52: 0 | G52: 0
A54: Fixed costs
A55: CAPEX | B55: € | C55: 172000000 | D55: 145000000 | E55: 80000000 | F55: 10150000 | G55: 121000000
...

Sheet Supplem.Table 15
B1: Unit | C1: AD SEW (thick) | D1: AD PIM (dw)
A2: Capacity
A3: Annual usage rate | B3: t a-1 | C3: 72000 | D3: 72000
A4: Life time | B4: a | C4: 20 | D4: 20
A6: Inputs
A7: Feedstock-type | C7: SEW (thick) | D7: PIM (dw)
A8: Feedstock-quantity | B8: t | C8: 1 | D8: 1
A9: Diesel | B9: L t-1 | C9: 0.29 | D9: 0.29
A10: Electricity | B10: kWh t-1 | C10: 6.18 | D10: 6.18
A11: Heat | B11: kWh t-1 | C11: 0δ | D11: 0δ
A12: Labour | B12: manh t-1 | C12: 0.007 | D12: 0.007
A14: Outputs
A15: Digestate | B15: kg TS t-1 | C15: 24 | D15: 135
A16: Biogas-Electricity | B16: kWh t-1 | C16: 2.1α | D16: 59γ
A18: Air emissions (fugitive)
A19: CH4 | B19: kg t-1 | C19: 0.2 | D19: 1.1
A20: CO2 biogenic | B20: kg t-1 | C20: 0.55 | D20: 3
A22: Air emissions
A23: (gas-engine)ε
A24: CH4 | B24: g MJ-1 | C24: 0.434 | D24: 0.434
A25: N2O | B25: g MJ-1 | C25: 0.202 | D25: 0.202
A26: NOx | B26: g MJ-1 | C26: 0.0016 | D26: 0.0016
A27: SOx | B27: g MJ-1 | C27: 0.434 | D27: 0.434
A28: CO2 biogenic | B28: kg t-1 | C28: 44 | D28: 239
A30: Fixed costs
A31: CAPEXζ | B31: € | C31: 2050000 | D31: 2050000
A32: Insurance | B32: %CAPEX | C32: 1.5 | D32: 1.5
A33: Maintenance | B33: %CAPEX | C33: 3 | D33: 3
A35: Fixed costs (per t)
A36: CAPEXη | B36: € t-1 | C36: 2.3 | D36: 2.3
A37: Insurance | B37: € t-1 | C37: 0.4 | D37: 0.4
A38: Maintenance | B38: € t-1 | C38: 0.9 | D38: 0.9
A39: α Corresponding to a methane production of 4.13 Nm3 CH4 (157 MJ).
A40: β Corresponding to a methane production of 0.84 Nm3 CH4 (32 MJ).
A41: γ Corresponding to a methane production of 3.23 Nm3 CH4 (123 MJ).
A42: δ It is assumed that the waste-heat from the gas engine is reused internally to heat the reactor (no external heat source required).
A43: ε Emissions are expressed per MJ of biogas-energy in input to the engine, based on ref. 13.
A44: ζ Based on the figures reported in ref. 14.
A45: η Annualised (Eq. 1 in Supplementary Methods) and divided by the annual usage rate (Eq. 2 in Supplementary Methods).

Sheet Supplem.Table 16
B1: Unit | C1: Wasstrip®- Ostara Pearl®
A2: Capacity
A3: Usage rate | B3: t a-1 | C3: 200000
A4: Life time | B4: a | C4: 20
A6: Inputs
A7: Feedstock-type | C7: SEW (dg dw)
A8: Feedstock-quantity | B8: t | C8: 1
A9: Electricity aeration | B9: kWh t-1 | C9: 0.026
A10: Polyelectrolyte | B10: kg t-1 | C10: 0.35
A11: Labour | B11: manh t-1 | C11: 0.042
A13: Outputs
A14: P-precipitate | B14: kg P t-1 | C14: 0.56
A15: P-wastewater | B15: kg P t-1 | C15: 0.072
A17: Fixed costs
A18: CAPEX | B18: € | C18: 1000000
A19: Insurance | B19: %CAPEX | C19: 1.5
A20: Maintenance | B20: %CAPEX | C20: 3
A22: Fixed costs (per t)
A23: CAPEX | B23: € t-1 | C23: 0.4
A24: Insurance | B24: € t-1 | C24: 0.08
A25: Maintenance | B25: € t-1 | C25: 0.15
A26: α Annualised (Eq. 1 in Supplementary Methods) and divided by the annual usage rate (Eq. 2 in Supplementary Methods)

Sheet Supplem.Table 17
B1: Unit | C1: Ashdec® | D1: Ecophos® | E1: MBM acidulation | F1: SSP acidulation
A2: Capacity
A3: Usage rate | B3: t a-1 | C3: 13800 | D3: 15000 | E3: 15000 | F3: 15000
A4: Life time | B4: a | C4: 20 | D4: 20 | E4: 20 | F4: 20
A6: Inputs
A7: Feedstock-type | C7: Ash | D7: Ash | E7: Ash | F7: Phosphate-rock
A8: Feedstock-quantity | B8: t | C8: 1 | D8: 1 | E8: 1 | F8: 1
A9: Ash-P | B9: kg P t-1 | C9: 122.5 | D9: 122.5 | E9: 98.34 | F9: 135
A10: CaOH2 | B10: kg t-1 | C10: 18 | D10: 0 | E10: 0 | F10: 0
A11: Electricity | B11: kWh t-1 | C11: 90 | D11: 30 | E11: 62.29 | F11: 33.53
A12: H2SO4 | B12: kg t-1 | C12: 0 | D12: 0 | E12: 458 | F12: 698.5
A13: HCl | B13: kg t-1 | C13: 0 | D13: 333 | E13: 0 | F13: 0
A14: Heat | B14: kWh t-1 | C14: 388.89 | D14: 2035 | E14: 0 | F14: 0
A15: NaOH | B15: kg t-1 | C15: 15 | D15: 0 | E15: 0 | F15: 0
A16: NaSO4 | B16: kg t-1 | C16: 370 | D16: 0 | E16: 0 | F16: 0
A17: Natural gas | B17: MJ t-1 | C17: 0 | D17: 0 | E17: 0.348 | F17: 0.46101
A18: Water | B18: kg t-1 | C18: 290 | D18: 0 | E18: 0 | F18: 0
A19: Labour | B19: manh t-1 | C19: 0.92 | D19: 0.56 | E19: 0.56 | F19: 0.56
A21: Outputs
A22: CaCl2 | B22: kg t-1 | C22: 0 | D22: 67 | E22: 0 | F22: 0
A23: FeCl3 | B23: kg t-1 | C23: 0 | D23: 41 | E23: 0 | F23: 0
A24: P (non-granulated) | B24: kg P t-1 | C24: 120.1α | D24: 121.3 | E24: 98.28 | F24: 134.9
A25: Waste | B25: kg TS t-1 | C25: 1.4 | D25: 5.4 | E25: 2 | F25: 0.1
A27: Fixed costs
A28: CAPEX | B28: € | C28: 11700000 | D28: 2400000 | E28: 2400000 | F28: 2400000
A29: Insurance | B29: %CAPEX | C29: 1.5 | D29: 1.5 | E29: 1.5 | F29: 1.5
A30: Maintenance | B30: %CAPEX | C30: 3 | D30: 3 | E30: 3 | F30: 3
A32: Fixed costs (per t)
A33: CAPEX | B33: € t-1 | C33: 68 | D33: 12.8 | E33: 12.8 | F33: 12.8
A34: Insurance | B34: € t-1 | C34: 4.2 | D34: 2.4 | E34: 2.4 | F34: 2.4
A35: Maintenance | B35: € t-1 | C35: 25.4 | D35: 4.8 | E35: 4.8 | F35: 4.8
A36: α Does not require granulation.
A37: β Annualised (Eq. 1 in Supplementary Methods) and divided by the annual usage rate (Eq. 2 in Supplementary Methods).

Sheet Supplem.Table 18
B1: Unit | C1: Composting
A2: Capacity
A3: Annual usage rate | B3: t a-1 | C3: 73000
A4: Life time | B4: a | C4: 20
A6: Inputs
A7: Feedstock-type | C7: PIM (dw)
A8: Feedstock-quantity | B8: t | C8: 1
A9: Diesel | B9: L t-1 | C9: 1
A10: Electricity | B10: kWh t-1 | C10: 6.3
A11: Labour | B11: manh t-1 | C11: 0.5
A13: Outputs
A14: Compost | B14: kg t-1 | C14: 400
A16: Air emissions (biofilters)
A17: Carbon dioxide, non-fossil | B17: air | C17: 62
A18: Methane, non-fossil | B18: air | C18: 0.008
A19: Nitrogen | B19: air | C19: 0.004
A20: Ammonia | B20: air | C20: 0.024
A21: Terpenes | B21: air | C21: 0.00011
A22: Hydrogen sulphide | B22: air | C22: 1.7e-05
A23: Dinitrogen monoxide | B23: air | C23: 0.045
A25: Fixed costs
A26: CAPEXα | B26: € | C26: 16000000
A27: Insurance | B27: %CAPEX | C27: 1.5
A28: Maintenance | B28: %CAPEX | C28: 3
A30: Fixed costs (per t)
A31: CAPEXβ | B31: € t-1 | C31: 17.5
A32: Insurance | B32: € t-1 | C32: 3.3
A33: Maintenance | B33: € t-1 | C33: 6.5
A34: α Calculated using the database reported in ref. 17.
A35: β Annualised (Eq. 1 in Supplementary Methods) and divided by the annual usage rate (Eq. 2 in Supplementary Methods).

Sheet Supplem.Table 19
A1: emissions | B1: fraction applied on land | C1: pathways | D1: unit | E1: Default | F1: min | G1: max | H1: reference/comment
A2: CH4 | B2: concentrated P-fertiliser | C2: AP1, AP2, AP3, AP4, AP5, RP | D2: % CH4 potential | E2: na | F2: na | G2: na | H2: no carbon in P-fertiliser
A3: CH4 | B3: concentrated P-fertiliser | C3: AP6 | D3: % CH4 potential | E3: 0 | F3: 0 | G3: 0 | H3: no emissions assumed for stable, dry materials
A4: CH4 | B4: digested sewage sludge | C4: AP1, CF1, CF3, CF4 | D4: % CH4 potential | E4: 5 | F4: 0 | G4: 17 | H4: ref.24
A5: CH4 | B5: liquid pig fraction (non-digested and digested) | C5: AP6, CF6 | D5: % CH4 potential | E5: 7 | F5: 0 | G5: 34 | H5: ref.23, as corrected for cover as per ref.21
A6: CH4 | B6: dried poultry litter | C6: CF2 | D6: % CH4 potential | E6: 1 | F6: 0 | G6: 2 | H6: ref.23, as corrected for cover as per ref.21
A7: CH4 | B7: meat and bone meal | C7: CF5 | D7: % CH4 potential | E7: 0 | F7: 0 | G7: 0 | H7: no emissions assumed for stable, dry materials
A8: CH4 | B8: solid pig manure (digested) | C8: CF6 | D8: % CH4 potential | E8: 0 | F8: 0 | G8: 0 | H8: emissions from liquid-solid separated material attrributed to liquid fraction
A9: N2O | B9: concentrated P-fertiliser | C9: AP1, AP2, AP3, AP4, AP5, RP | D9: % N | E9: na | F9: na | G9: na | H9: no nitrogen in P-fertiliser
A10: N2O | B10: concentrated P-fertiliser | C10: AP6 | D10: % N | E10: 0 | F10: 0 | G10: 0 | H10: no emissions assumed for stable, dry materials
A11: N2O | B11: digested rest sludge | C11: AP1, CF1, CF3, CF4 | D11: % N | E11: 0.2 | F11: 0 | G11: 0.5 | H11: ref.24
A12: N2O | B12: liquid pig fraction (non-digested and digested) | C12: AP6, CF6 | D12: % N | E12: 0.2 | F12: 0 | G12: 1 | H12: ref.21
A13: N2O | B13: dried poultry litter | C13: CF2 | D13: % N | E13: 0.5 | F13: 0 | G13: 1.7 | H13: ref.21
A14: N2O | B14: meat and bone meal | C14: CF5 | D14: % N | E14: 0 | F14: 0 | G14: 0 | H14: no emissions assumed for stable, dry materials
A15: N2O | B15: solid pig manure (digested) | C15: CF6 | D15: % N | E15: 0 | F15: 0 | G15: 0 | H15: emissions from liquid-solid separated material attrributed to liquid fraction
A16: NH3 | B16: concentrated P-fertiliser | C16: AP1, AP2, AP3, AP4, AP5, RP | D16: % N | E16: na | F16: na | G16: na | H16: na
A17: NH3 | B17: concentrated P-fertiliser | C17: AP6 | D17: % N | E17: 0 | F17: 0 | G17: 0 | H17: biochar stability assumption
A18: NH3 | B18: digested rest sludge | C18: AP1, CF1, CF3, CF4 | D18: % N | E18: 0.5 | F18: 0 | G18: 2 | H18: no data as outlined in ref.24; estimate based on manure data
A19: NH3 | B19: liquid pig fraction (non-digested and digested) | C19: AP6, CF6 | D19: % N | E19: 0.5 | F19: 0 | G19: 2 | H19: ref.19, as corrected for cover as per ref.21
A20: NH3 | B20: dried poultry litter | C20: CF2 | D20: % N | E20: 3.6 | F20: 2 | G20: 8 | H20: refs.21-23, 25
A21: NH3 | B21: meat and bone meal | C21: CF5 | D21: % N | E21: 0 | F21: 0 | G21: 0 | H21: no emissions assumed for stable, dry materials
A22: NH3 | B22: solid pig manure (digested) | C22: CF6 | D22: % N | E22: 0 | F22: 0 | G22: 0 | H22: emissions from liquid-solid separated material attrributed to liquid fraction

Sheet Supplem.Table 20
A1: Product | B1: Unit | C1: Background life cycle inventory | D1: Unit-cost | E1: Source
A2: Activated carbon | B2: € kg-1 | C2: market for activated carbon, granular, GLO | D2: 1 | E2: ref.2
A3: Ammonium nitrate, as N | B3: € kg-1 | C3: urea ammonium nitrate production; RoW | D3: 0.61 | E3: ref.46
